Workbook
Name _______bot1: #REF!
Name _______bot3: #REF!
Name _______bot4: #REF!
Name _______bot5: #REF!
Name _______bot6: #REF!
Name _______top1: #REF!
Name _______top2: #REF!
Name _______top3: #REF!
Name _______top4: #REF!
Name _______top5: #REF!
Name _______top6: #REF!
Name ______bot2: #REF!
Name _____bot1: #REF!
Name _____bot3: #REF!
Name _____bot4: #REF!
Name _____bot5: #REF!
Name _____bot6: #REF!
Name _____top1: #REF!
Name _____top2: #REF!
Name _____top3: #REF!
Name _____top4: #REF!
Name _____top5: #REF!
Name _____top6: #REF!
Name ____bot1: #REF!
Name ____bot2: #REF!
Name ____bot3: #REF!
Name ____bot4: #REF!
Name ____bot5: #REF!
Name ____bot6: #REF!
Name ____top1: #REF!
Name ____top2: #REF!
Name ____top3: #REF!
Name ____top4: #REF!
Name ____top5: #REF!
Name ____top6: #REF!
Name ___bot1: #REF!
Name ___bot2: #REF!
Name ___bot3: #REF!
Name ___bot4: #REF!
Name ___bot5: #REF!
Name ___bot6: #REF!
Name ___top1: #REF!
Name ___top2: #REF!
Name ___top3: #REF!
Name ___top4: #REF!
Name ___top5: #REF!
Name ___top6: #REF!
Name __bot1: #REF!
Name __bot2: #REF!
Name __bot3: #REF!
Name __bot4: #REF!
Name __bot5: #REF!
Name __bot6: #REF!
Name __top1: #REF!
Name __top2: #REF!
Name __top3: #REF!
Name __top4: #REF!
Name __top5: #REF!
Name __top6: #REF!
Name _bot1: #REF!

Sheet How to update
B2: How to update
B3: 1. | C3: Navigate to the tabs included in the 'Data Links' tab at the bottom of this spreadsheet
B4: 2. | C4: Starting with the first link, download the data and open the downloaded spreadsheet
B5: 3. | C5: In the downloaded spreadsheet, find the tab that contains the same data as the tab in this spreadsheet that you are trying to update and copy all of the data and only the data
B6: 4. | C6: Line the first month of the copied data up with the first month in the tab you are hoping to update and paste the new data on top of it, overwriting the old data (i.e. July 2014 should be pasted on top of July 2014)
B7: 5. | C7: Repeat for all tabs until the spreadsheet is completely updated
B8: 6. | C8: Do a quick comparison with the ONS published stats to make sure all the formulas are pulling through correctly
B9: 7. | C9: To update the dashboard, ensure the yellow date box in the top left hand corner of the dashboard tab is set to the correct value

Sheet Data links
B2: Tab | C2: Data link (August - Make sure to download most recent month!!!)
B3: 1. Payrolled employees | C3: https://www.ons.gov.uk/employmentandlabourmarket/peopleinwork/earningsandworkinghours/datasets/realtimeinformationstatisticsreferencetableseasonallyadjusted
B4: 23. Employees Industry
B5: 2, 5, 10, 11, 13, 15, 18, 20, 21 | C5: A01: Summary of labour market statistics - Office for National Statistics
B6: 1 UK (Claimant count) | C6: CLA01: Claimant Count - Office for National Statistics
B7: Real Average Weekly Earnings (using CPI) | C7: X09: Real average weekly earnings using consumer price inflation (seasonally adjusted) - Office for National Statistics
B8: Redundancies | C8: HR1: Potential redundancies - Office for National Statistics
B9: Labour market flows | C9: X02: Labour Force Survey flows estimates

Sheet Dashboard
B1: Aug-Oct | L1: Dropdowns: | M1: Month | N1: Offset Count | O1: Year
A2: Year | B2: 2025 | M2: Nov-Jan | N2: 13 | O2: 2022
A3: Offset factor | B3: =((VLOOKUP(B1,$M$2:$N$13, 2, FALSE)-0)+((Dashboard!B2-2024)*12)) -> 34 | M3: Dec-Feb | N3: =N2+1 -> 14 | O3: 2023
M4: Jan-Mar | N4: =N3+1 -> 15 | O4: 2024
B5: ="Key Metrics, "&B1&" "&B2 -> Key Metrics, Aug-Oct 2025 | D5: Current | E5: Change on quarter | F5: Change on the year | G5: Change since Covid-20 | I5: Good or Bad' formatting? | K5: For data showing percentage point change | M5: Feb-Apr | N5: =N4+1 -> 16 | O5: 2025
B6: Employment (000s) 16+ | D6: =OFFSET('2'!$B$385,$B$3,0) -> 34226340 | E6: ='2'!J6 -> -60087.846 | F6: ='2'!J7 -> 255911.47 | G6: ='2'!J8 -> 672666.1 | I6: Minus = Bad | M6: Mar-May | N6: =N5+1 -> 17 | O6: 2026
B7: Employment rate (16-64) | D7: =OFFSET('2'!$K$385,$B$3,0)/100 -> 0.74915831 | E7: ='2'!K6 -> -0.25826284 | F7: ='2'!K7 -> 0.013358069 | G7: ='2'!K8 -> -1.5750361 | I7: Minus = Bad | K7: Add 'pp' in brief | M7: Apr-Jun | N7: =N6+1 -> 18 | O7: 2027
B8: Unemployment, 16+ (000s) | D8: =OFFSET('2'!$D$385,$B$3,0) -> 1831890.1 | E8: ='2'!D6 -> 157870.54 | F8: ='2'!D7 -> 326867.79 | G8: ='2'!D8 -> 468168.17 | I8: Minus = Good | M8: May-Jul | N8: =N7+1 -> 19 | O8: 2028
B9: Unemployment rate, 16+ | D9: =OFFSET('2'!$E$385,$B$3,0)/100 -> 0.050803661 | E9: ='2'!E6 -> 0.41951154 | F9: ='2'!E7 -> 0.81482364 | G9: ='2'!E8 -> 1.1327015 | I9: Minus = Good | K9: Add 'pp' in brief | M9: Jun-Aug | N9: =N8+1 -> 20 | O9: 2029
B10: Economic inactivity (000s) (16-64) | D10: =OFFSET('2'!$P$385,$B$3,0) -> 9098658.3 | E10: ='2'!P6 -> -25615.944 | F10: ='2'!P7 -> -234336.28 | G10: ='2'!P8 -> 652867.86 | I10: Minus = Good | M10: Jul-Sep | N10: =N9+1 -> 21 | O10: 2030
B11: Economic inactivity rate (16-64) | D11: =OFFSET('2'!$Q$385,$B$3,0)/100 -> 0.20981876 | E11: ='2'!Q6 -> -0.092627813 | F11: ='2'!Q7 -> -0.70740664 | G11: ='2'!Q8 -> 0.67560951 | I11: Minus = Good | K11: Add 'pp' in brief | M11: Aug-Oct | N11: =N10+1 -> 22
B12: 50-64s inactivity (000s) | D12: =OFFSET('2'!$BD$385,$B$3,0) -> 3457561.5 | E12: ='2'!BD6 -> -10258.327 | F12: ='2'!BD7 -> -90729.299 | G12: ='2'!BD8 -> 227915.35 | I12: Minus = Good | M12: Sep-Nov | N12: =N11+1 -> 23
B13: 50-64s inactivity rate | D13: =OFFSET('2'!$BE$385,$B$3,0)/100 -> 0.26131915 | E13: ='2'!BE6 -> -0.0437376 | F13: ='2'!BE7 -> -0.61936257 | G13: ='2'!BE8 -> 1.021681 | I13: Minus = Good | K13: Add 'pp' in brief | M13: Oct-Dec | N13: =N12+1 -> 24
B14: Provisional December 2024 HMRC Payroll employees (000s) | D14: =OFFSET('1. Payrolled employees (UK)'!B113,$B$3,0) -> 30256482 | E14: ='1. Payrolled employees (UK)'!D2 -> -49095.667 | F14: ='1. Payrolled employees (UK)'!E2 -> -142627 | G14: ='1. Payrolled employees (UK)'!F2 -> 1259184.3 | I14: Minus = Bad
A15: *note: covid period is different (Jan-Mar) due to reporting periods | B15: Provisional Nov 2024-Jan 2025 Vacancies (000s) | D15: =OFFSET('20'!C276,$B$3,0) -> 729 | E15: ='20'!B3 -> -2 | F15: ='20'!B4 -> -78 | G15: ='20'!B5 -> -66 | I15: Do not format
B16: Wage growth in cash terms (total pay, including bonuses, yearly % change) | C16: Change in annual earnings | D16: =OFFSET('13'!D293, $B$3,0)/100 -> 0.047190575 | E16: ='13'!B5 -> 523.61043 | F16: ='13'!B6 -> 1722.8963 | G16: ='13'!B7 -> 9895.5919 | I16: Minus = Bad
B17: Wage growth adjusted for inflation (total pay, including bonuses, yearly % change) | D17: =OFFSET('AWE Real_CPI'!E292,$B$3,0)/100 -> 0.0096785559 | E17: ='AWE Real_CPI'!B3 -> 142.57626 | F17: ='AWE Real_CPI'!B4 -> 263.19994 | G17: ='AWE Real_CPI'!B5 -> 1529.8116 | I17: Minus = Bad

Sheet 1. Payrolled employees (UK)
B1: Current | C1: Change on month (singular) | D1: Change on quarter | E1: Change year on year | F1: Change since Covid-19 | G1: Change since 2024 election | H1: Change since coming into office | I1: Change since start of the year | J1: Max
A2: Number | B2: =AVERAGE(OFFSET(INDEX($B$11:$B$1048576,COUNTA($B$11:$B$1048576)),-2,0,3,1)) -> 30289110 | C2: {=INDEX($B$11:$B$1048576,COUNTA($B$11:$B$1048576))-INDEX($B$11:$B$1048576,COUNTA($B$11:$B$1048576)-1)} -> -37996 | D2: =AVERAGE(OFFSET(INDEX($B$11:$B$1048576,COUNTA($B$11:$B$1048576)),-2,0,3,1))-AVERAGE(OFFSET(INDEX($B$11:$B$1048576,COUNTA($B$11:$B$1048576)),-5,0,3,1)) -> -49095.667 | E2: =AVERAGE(OFFSET(INDEX($B$11:$B$1048576,COUNTA($B$11:$B$1048576)),-2,0,3,1))-AVERAGE(OFFSET(INDEX($B$11:$B$1048576,COUNTA($B$11:$B$1048576)),-14,0,3,1)) -> -142627 | F2: =AVERAGE(OFFSET(INDEX($B$11:$B$1048576,COUNTA($B$11:$B$1048576)),-2,0,3,1))-AVERAGE($B$76:$B$78) -> 1259184.3 | G2: =AVERAGE(OFFSET(INDEX($B$11:$B$1048576,COUNTA($B$11:$B$1048576)),-2,0,3,1))-AVERAGE($B$128:$B$130) -> -139202.67 | H2: {=INDEX($B$11:$B$1048576,COUNTA($B$11:$B$1048576))-$B$130} -> -187431 | I2: {=INDEX(B$11:B$1048576,COUNTA(B$11:B$1048576))-_xlfn.XLOOKUP("January " & TEXT(TODAY(),"yyyy"),A$11:A$1048576,B$11:B$1048576)} -> -154900 | J2: =MAX($B$11:$B$1048576) -> 30450219
A3: % | C3: {=INDEX($B$11:$B$1048576,COUNTA($B$11:$B$1048576))/INDEX($B$11:$B$1048576,COUNTA($B$11:$B$1048576)-1)-1} -> -0.001254222 | D3: =AVERAGE(OFFSET(INDEX($B$11:$B$1048576,COUNTA($B$11:$B$1048576)),-2,0,3,1))/AVERAGE(OFFSET(INDEX($B$11:$B$1048576,COUNTA($B$11:$B$1048576)),-5,0,3,1))-1 -> -0.0016182785 | E3: =AVERAGE(OFFSET(INDEX($B$11:$B$1048576,COUNTA($B$11:$B$1048576)),-2,0,3,1))/AVERAGE(OFFSET(INDEX($B$11:$B$1048576,COUNTA($B$11:$B$1048576)),-14,0,3,1))-1 -> -0.0046867848 | F3: {=INDEX($B$11:$B$1048576,COUNTA($B$11:$B$1048576))/AVERAGE($B$76:$B$78)-1} -> 0.042251458 | G3: =AVERAGE(OFFSET(INDEX($B$11:$B$1048576,COUNTA($B$11:$B$1048576)),-2,0,3,1))/AVERAGE($B$128:$B$130)-1 -> -0.0045747745 | H3: {=INDEX($B$11:$B$1048576,COUNTA($B$11:$B$1048576))/$B$130-1} -> -0.0061566002 | I3: {=INDEX(B$11:B$1048576,COUNTA(B$11:B$1048576))/_xlfn.XLOOKUP("January " & TEXT(TODAY(),"yyyy"),A$11:A$1048576,B$11:B$1048576)-1} -> -0.0050934877
A5: 1. Payrolled employee counts from PAYE RTI
A6: UK, all industries, seasonally adjusted
A8: Units | B8: Payrolled employees
A10: Date | B10: Payrolled employees | C10: Change on previous month
A11: July 2014 | B11: 26762113
A12: August 2014 | B12: 26837223 | C12: 75110
A13: September 2014 | B13: 26892127 | C13: 54904
A14: October 2014 | B14: 26906169 | C14: 14042
A15: November 2014 | B15: 27000958 | C15: 94789
A16: December 2014 | B16: 26998286 | C16: -2672
A17: January 2015 | B17: 27157573 | C17: 159287
A18: February 2015 | B18: 27214499 | C18: 56926
A19: March 2015 | B19: 27294543 | C19: 80044
A20: April 2015 | B20: 27340654 | C20: 46111
A21: May 2015 | B21: 27398974 | C21: 58320
A22: June 2015 | B22: 27461315 | C22: 62341
A23: July 2015 | B23: 27519284 | C23: 57969
... A77: January 2020 | B77: 29054506 | C77: 59878
A78: February 2020 | B78: 29040642 | C78: -13864 | E78: =AVERAGE(B76:B78) -> 29029925
A79: March 2020 | B79: 29015447 | C79: -25195 | E79: =AVERAGE(B143:B145) -> 30331906
A80: April 2020 | B80: 28561484 | C80: -453963 | E80: =E79-E78 -> 1301980.3
A81: May 2020 | B81: 28406852 | C81: -154632
A82: June 2020 | B82: 28352191 | C82: -54661
A83: July 2020 | B83: 28321060 | C83: -31131
A84: August 2020 | B84: 28256016 | C84: -65044
A85: September 2020 | B85: 28193180 | C85: -62836
A86: October 2020 | B86: 28162587 | C86: -30593
A87: November 2020 | B87: 28086479 | C87: -76108
A88: December 2020 | B88: 28124206 | C88: 37727
A89: January 2021 | B89: 28164763 | C89: 40557
A90: February 2021 | B90: 28159854 | C90: -4909
A91: March 2021 | B91: 28207157 | C91: 47303
A92: April 2021 | B92: 28318611 | C92: 111454
... A144: August 2025 | B144: 30344181 | C144: 9014
A145: September 2025 | B145: 30316369 | C145: -27812 | H145: =F145/B145 -> 0
A146: October 2025 | B146: 30294478 | C146: -21891
A147: November 2025 | B147: 30256482 | C147: -37996

Sheet 23. Employees Industry
A1: Yearly change | B1: Agriculture, forestry and fishing | C1: Mining and quarrying | D1: Manufacturing | E1: Energy production and supply | F1: Water supply, sewerage and waste | G1: Construction | H1: Wholesale and retail; repair of motor vehicles | I1: Transportation and storage | J1: Accommodation and food service activities | K1: Information and communication | L1: Finance and insurance | M1: Real estate | N1: Professional, scientific and technical | O1: Administrative and support services | P1: Public administration and defence; social security | Q1: Education | R1: Health and social work | S1: Arts, entertainment and recreation | T1: Other service activities | U1: Households and Extraterritorial | V1: UK
A2: Number | B2: {=INDEX(B$12:B$1048576,COUNTA(B$12:B$1048576))-INDEX(B$12:B$1048576,COUNTA(B$12:B$1048576)-12)} -> -614 | C2: {=INDEX(C$12:C$1048576,COUNTA(C$12:C$1048576))-INDEX(C$12:C$1048576,COUNTA(C$12:C$1048576)-12)} -> -1901 | D2: {=INDEX(D$12:D$1048576,COUNTA(D$12:D$1048576))-INDEX(D$12:D$1048576,COUNTA(D$12:D$1048576)-12)} -> -30376 | E2: {=INDEX(E$12:E$1048576,COUNTA(E$12:E$1048576))-INDEX(E$12:E$1048576,COUNTA(E$12:E$1048576)-12)} -> 4496 | F2: {=INDEX(F$12:F$1048576,COUNTA(F$12:F$1048576))-INDEX(F$12:F$1048576,COUNTA(F$12:F$1048576)-12)} -> 6119 | G2: {=INDEX(G$12:G$1048576,COUNTA(G$12:G$1048576))-INDEX(G$12:G$1048576,COUNTA(G$12:G$1048576)-12)} -> -12288 | H2: {=INDEX(H$12:H$1048576,COUNTA(H$12:H$1048576))-INDEX(H$12:H$1048576,COUNTA(H$12:H$1048576)-12)} -> -70055 | I2: {=INDEX(I$12:I$1048576,COUNTA(I$12:I$1048576))-INDEX(I$12:I$1048576,COUNTA(I$12:I$1048576)-12)} -> 16154 | ... V2: {=INDEX(V$12:V$1048576,COUNTA(V$12:V$1048576))-INDEX(V$12:V$1048576,COUNTA(V$12:V$1048576)-12)} -> -170685
A3: % | B3: {=INDEX(B$12:B$1048576,COUNTA(B$12:B$1048576))/INDEX(B$12:B$1048576,COUNTA(B$12:B$1048576)-12)-1} -> -0.0031230449 | C3: {=INDEX(C$12:C$1048576,COUNTA(C$12:C$1048576))/INDEX(C$12:C$1048576,COUNTA(C$12:C$1048576)-12)-1} -> -0.041632903 | D3: {=INDEX(D$12:D$1048576,COUNTA(D$12:D$1048576))/INDEX(D$12:D$1048576,COUNTA(D$12:D$1048576)-12)-1} -> -0.012996732 | E3: {=INDEX(E$12:E$1048576,COUNTA(E$12:E$1048576))/INDEX(E$12:E$1048576,COUNTA(E$12:E$1048576)-12)-1} -> 0.038712233 | F3: {=INDEX(F$12:F$1048576,COUNTA(F$12:F$1048576))/INDEX(F$12:F$1048576,COUNTA(F$12:F$1048576)-12)-1} -> 0.029626223 | G3: {=INDEX(G$12:G$1048576,COUNTA(G$12:G$1048576))/INDEX(G$12:G$1048576,COUNTA(G$12:G$1048576)-12)-1} -> -0.0091847489 | H3: {=INDEX(H$12:H$1048576,COUNTA(H$12:H$1048576))/INDEX(H$12:H$1048576,COUNTA(H$12:H$1048576)-12)-1} -> -0.016213324 | I3: {=INDEX(I$12:I$1048576,COUNTA(I$12:I$1048576))/INDEX(I$12:I$1048576,COUNTA(I$12:I$1048576)-12)-1} -> 0.011613487 | ... V3: {=INDEX(V$12:V$1048576,COUNTA(V$12:V$1048576))/INDEX(V$12:V$1048576,COUNTA(V$12:V$1048576)-12)-1} -> -0.0056096251
A4: Rank | B4: =RANK(B2,$B$2:$U$2) -> 9 | C4: =RANK(C2,$B$2:$U$2) -> 10 | D4: =RANK(D2,$B$2:$U$2) -> 17 | E4: =RANK(E2,$B$2:$U$2) -> 8 | F4: =RANK(F2,$B$2:$U$2) -> 6 | G4: =RANK(G2,$B$2:$U$2) -> 14 | H4: =RANK(H2,$B$2:$U$2) -> 20 | I4: =RANK(I2,$B$2:$U$2) -> 2 | ... U4: =RANK(U2,$B$2:$U$2) -> 12
A5: 23. Payrolled employees from PAYE RTI
A6: UK, seasonally adjusted
A7: Earnings and employment from Pay As You Earn Real Time Information, seasonally adjusted - Office for National Statistics
A8: Units | B8: Payrolled employees
B10: A | C10: B | D10: C | E10: D | F10: E | G10: F | H10: G | I10: H | J10: I | K10: J | L10: K | M10: L | N10: M | O10: N | P10: O | Q10: P | R10: Q | S10: R | T10: S | U10: T-U
A11: Date | B11: Agriculture, forestry and fishing | C11: Mining and quarrying | D11: Manufacturing | E11: Energy production and supply | F11: Water supply, sewerage and waste | G11: Construction | H11: Wholesale and retail; repair of motor vehicles | I11: Transportation and storage | J11: Accommodation and food service activities | K11: Information and communication | L11: Finance and insurance | M11: Real estate | N11: Professional, scientific and technical | O11: Administrative and support services | P11: Public administration and defence; social security | Q11: Education | R11: Health and social work | S11: Arts, entertainment and recreation | T11: Other service activities | U11: Households and Extraterritorial | V11: UK
A12: July 2014 | B12: 177905 | C12: 58307 | D12: 2336087 | E12: 92943 | F12: 155653 | G12: 1081408 | H12: 4255533 | I12: 1164523 | J12: 1758770 | K12: 1060896 | L12: 1054685 | M12: 401247 | N12: 1934869 | O12: 2230040 | P12: 1588018 | Q12: 2879249 | R12: 3429105 | S12: 520128 | T12: 486204 | U12: 96542 | V12: 26762113
A13: August 2014 | B13: 178179 | C13: 58487 | D13: 2340535 | E13: 92980 | F13: 155943 | G13: 1087984 | H13: 4264797 | I13: 1165997 | J13: 1767010 | K13: 1066653 | L13: 1055820 | M13: 401904 | N13: 1943596 | O13: 2250253 | P13: 1584818 | Q13: 2881488 | R13: 3435643 | S13: 521066 | T13: 487131 | U13: 96940 | V13: 26837223
A14: September 2014 | B14: 177495 | C14: 58694 | D14: 2346087 | E14: 92853 | F14: 156177 | G14: 1093244 | H14: 4271407 | I14: 1169435 | J14: 1775315 | K14: 1069876 | L14: 1057134 | M14: 402426 | N14: 1950604 | O14: 2247490 | P14: 1583955 | Q14: 2894249 | R14: 3438641 | S14: 520971 | T14: 488583 | U14: 97491 | V14: 26892127
A15: October 2014 | B15: 176020 | C15: 58675 | D15: 2347383 | E15: 92877 | F15: 156256 | G15: 1097393 | H15: 4273008 | I15: 1168777 | J15: 1779273 | K15: 1071208 | L15: 1056146 | M15: 402339 | N15: 1957542 | O15: 2250103 | P15: 1578449 | Q15: 2891568 | R15: 3437878 | S15: 523690 | T15: 489885 | U15: 97699 | V15: 26906169
A16: November 2014 | B16: 177002 | C16: 58750 | D16: 2355064 | E16: 93182 | F16: 156820 | G16: 1104660 | H16: 4289831 | I16: 1173413 | J16: 1789505 | K16: 1075709 | L16: 1058097 | M16: 403228 | N16: 1968659 | O16: 2259100 | P16: 1578004 | Q16: 2895515 | R16: 3448268 | S16: 526409 | T16: 491726 | U16: 98015 | V16: 27000958
A17: December 2014 | B17: 178028 | C17: 58391 | D17: 2317834 | E17: 93448 | F17: 156531 | G17: 1084425 | H17: 4307019 | I17: 1176347 | J17: 1794077 | K17: 1079444 | L17: 1058427 | M17: 403689 | N17: 1973548 | O17: 2266343 | P17: 1575803 | Q17: 2898731 | R17: 3456646 | S17: 528625 | T17: 492350 | U17: 98580 | V17: 26998286
A18: January 2015 | B18: 178603 | C18: 58458 | D18: 2358927 | E18: 93625 | F18: 157927 | G18: 1117623 | H18: 4325847 | I18: 1183740 | J18: 1805912 | K18: 1083161 | L18: 1060588 | M18: 405182 | N18: 1980759 | O18: 2279879 | P18: 1573725 | Q18: 2901669 | R18: 3468093 | S18: 530428 | T18: 494311 | U18: 99116 | V18: 27157573
A19: February 2015 | B19: 178621 | C19: 57880 | D19: 2364907 | E19: 93778 | F19: 158501 | G19: 1119773 | H19: 4336022 | I19: 1187701 | J19: 1807320 | K19: 1089437 | L19: 1061180 | M19: 405416 | N19: 1992950 | O19: 2288539 | P19: 1569097 | Q19: 2901169 | R19: 3474682 | S19: 532809 | T19: 495242 | U19: 99475 | V19: 27214499
A20: March 2015 | B20: 178987 | C20: 57636 | D20: 2367842 | E20: 94093 | F20: 158988 | G20: 1126149 | H20: 4347421 | I20: 1191409 | J20: 1815637 | K20: 1095568 | L20: 1062977 | M20: 406721 | N20: 2008036 | O20: 2301315 | P20: 1565246 | Q20: 2903120 | R20: 3481996 | S20: 534688 | T20: 496790 | U20: 99923 | V20: 27294543
A21: April 2015 | B21: 179859 | C21: 55897 | D21: 2370463 | E21: 92731 | F21: 158857 | G21: 1132002 | H21: 4341372 | I21: 1189319 | J21: 1829538 | K21: 1095929 | L21: 1074624 | M21: 408254 | N21: 2020610 | O21: 2292050 | P21: 1563235 | Q21: 2904107 | R21: 3497763 | S21: 535741 | T21: 497816 | U21: 100486 | V21: 27340654
A22: May 2015 | B22: 180610 | C22: 55443 | D22: 2370582 | E22: 93205 | F22: 159168 | G22: 1136838 | H22: 4351394 | I22: 1192362 | J22: 1838931 | K22: 1099678 | L22: 1075060 | M22: 408890 | N22: 2027810 | O22: 2295487 | P22: 1569710 | Q22: 2900585 | R22: 3504968 | S22: 538501 | T22: 498657 | U22: 101096 | V22: 27398974
A23: June 2015 | B23: 181683 | C23: 54872 | D23: 2375700 | E23: 93850 | F23: 160027 | G23: 1143893 | H23: 4365722 | I23: 1198270 | J23: 1850234 | K23: 1105687 | L23: 1079142 | M23: 410606 | N23: 2037582 | O23: 2293723 | P23: 1548667 | Q23: 2903625 | R23: 3517935 | S23: 541917 | T23: 499535 | U23: 98645 | V23: 27461315
... A148: November 2025 | B148: 195989 | C148: 43760 | D148: 2306827 | E148: 120635 | F148: 212659 | G148: 1325582 | H148: 4250774 | I148: 1407123 | J148: 2129683 | K148: 1257532 | L148: 1104923 | M148: 471901 | N148: 2463249 | O148: 2393911 | P148: 1594167 | Q148: 3160819 | R148: 4506248 | S148: 649500 | T148: 543816 | U148: 117385 | V148: 30256482

Sheet 2
B2: Aged 16 and over | J2: Aged 16-64 | R2: Aged 16-17 | Z2: Aged 18-24 | AH2: Aged 25-34 | AP2: Aged 35-49 | AX2: Aged 50-64 | BF2: Age 65+
B3: Employment | D3: Unemployment | F3: Activity | H3: Inactivity | J3: Employment | L3: Unemployment | N3: Activity | P3: Inactivity | R3: Employment | T3: Unemployment | V3: Activity | X3: Inactivity | Z3: Employment | AB3: Unemployment | AD3: Activity | AF3: Inactivity | AH3: Employment | AJ3: Unemployment | AL3: Activity | AN3: Inactivity | AP3: Employment | AR3: Unemployment | AT3: Activity | AV3: Inactivity | AX3: Employment | AZ3: Unemployment | BB3: Activity | BD3: Inactivity | BF3: Employment | BH3: Unemployment | BJ3: Activity | BL3: Inactivity
B4: level | C4: rate (%) | D4: level | E4: rate (%) | F4: level | G4: rate (%) | H4: level | I4: rate (%) | J4: level | K4: rate (%) | L4: level | M4: rate (%) | N4: level | O4: rate (%) | P4: level | Q4: rate (%) | R4: level | S4: rate (%) | T4: level | U4: rate (%) | V4: level | W4: rate (%) | X4: level | Y4: rate (%) | Z4: level | AA4: rate (%) | AB4: level | AC4: rate (%) | AD4: level | AE4: rate (%) | AF4: level | AG4: rate (%) | AH4: level | AI4: rate (%) | AJ4: level | AK4: rate (%) | AL4: level | AM4: rate (%) | AN4: level | AO4: rate (%) | AP4: level | AQ4: rate (%) | AR4: level | AS4: rate (%) | AT4: level | AU4: rate (%) | AV4: level | AW4: rate (%) | AX4: level | AY4: rate (%) | AZ4: level | BA4: rate (%) | BB4: level | BC4: rate (%) | BD4: level | BE4: rate (%) | BF4: level | BG4: rate (%) | BH4: level | BI4: rate (%) | BJ4: level | BK4: rate (%) | BL4: level | BM4: rate (%)
A5: Current | B5: {=INDEX(B$18:B$1048576,COUNTA(B$18:B$1048576))} -> 34226340 | C5: {=INDEX(C$18:C$1048576,COUNTA(C$18:C$1048576))} -> 60.689871 | D5: {=INDEX(D$18:D$1048576,COUNTA(D$18:D$1048576))} -> 1831890.1 | E5: {=INDEX(E$18:E$1048576,COUNTA(E$18:E$1048576))} -> 5.0803661 | F5: {=INDEX(F$18:F$1048576,COUNTA(F$18:F$1048576))} -> 36058230 | G5: {=INDEX(G$18:G$1048576,COUNTA(G$18:G$1048576))} -> 63.938164 | H5: {=INDEX(H$18:H$1048576,COUNTA(H$18:H$1048576))} -> 20337243 | I5: {=INDEX(I$18:I$1048576,COUNTA(I$18:I$1048576))} -> 36.061836 | ... BM5: {=INDEX(BM$18:BM$1048576,COUNTA(BM$18:BM$1048576))} -> 86.244309
A6: Quarterly change | B6: {=INDEX(B$18:B$1048576,COUNTA(B$18:B$1048576))-INDEX(B$18:B$1048576,COUNTA(B$18:B$1048576)-3)} -> -16220.426 | C6: {=INDEX(C$18:C$1048576,COUNTA(C$18:C$1048576))-INDEX(C$18:C$1048576,COUNTA(C$18:C$1048576)-3)} -> -0.17271674 | D6: {=INDEX(D$18:D$1048576,COUNTA(D$18:D$1048576))-INDEX(D$18:D$1048576,COUNTA(D$18:D$1048576)-3)} -> 157870.54 | E6: {=INDEX(E$18:E$1048576,COUNTA(E$18:E$1048576))-INDEX(E$18:E$1048576,COUNTA(E$18:E$1048576)-3)} -> 0.41951154 | F6: {=INDEX(F$18:F$1048576,COUNTA(F$18:F$1048576))-INDEX(F$18:F$1048576,COUNTA(F$18:F$1048576)-3)} -> 141650.12 | G6: {=INDEX(G$18:G$1048576,COUNTA(G$18:G$1048576))-INDEX(G$18:G$1048576,COUNTA(G$18:G$1048576)-3)} -> 0.1001805 | H6: {=INDEX(H$18:H$1048576,COUNTA(H$18:H$1048576))-INDEX(H$18:H$1048576,COUNTA(H$18:H$1048576)-3)} -> -8261.1158 | I6: {=INDEX(I$18:I$1048576,COUNTA(I$18:I$1048576))-INDEX(I$18:I$1048576,COUNTA(I$18:I$1048576)-3)} -> -0.1001805 | ... BM6: {=INDEX(BM$18:BM$1048576,COUNTA(BM$18:BM$1048576))-INDEX(BM$18:BM$1048576,COUNTA(BM$18:BM$1048576)-3)} -> -0.29410289
A7: Change year on year | B7: {=INDEX(B$18:B$1048576,COUNTA(B$18:B$1048576))-INDEX(B$18:B$1048576,COUNTA(B$18:B$1048576)-12)} -> 448105.34 | C7: {=INDEX(C$18:C$1048576,COUNTA(C$18:C$1048576))-INDEX(C$18:C$1048576,COUNTA(C$18:C$1048576)-12)} -> 0.17645127 | D7: {=INDEX(D$18:D$1048576,COUNTA(D$18:D$1048576))-INDEX(D$18:D$1048576,COUNTA(D$18:D$1048576)-12)} -> 326867.79 | E7: {=INDEX(E$18:E$1048576,COUNTA(E$18:E$1048576))-INDEX(E$18:E$1048576,COUNTA(E$18:E$1048576)-12)} -> 0.81482364 | F7: {=INDEX(F$18:F$1048576,COUNTA(F$18:F$1048576))-INDEX(F$18:F$1048576,COUNTA(F$18:F$1048576)-12)} -> 774973.13 | G7: {=INDEX(G$18:G$1048576,COUNTA(G$18:G$1048576))-INDEX(G$18:G$1048576,COUNTA(G$18:G$1048576)-12)} -> 0.72850942 | H7: {=INDEX(H$18:H$1048576,COUNTA(H$18:H$1048576))-INDEX(H$18:H$1048576,COUNTA(H$18:H$1048576)-12)} -> -198911.13 | I7: {=INDEX(I$18:I$1048576,COUNTA(I$18:I$1048576))-INDEX(I$18:I$1048576,COUNTA(I$18:I$1048576)-12)} -> -0.72850942 | ... BM7: {=INDEX(BM$18:BM$1048576,COUNTA(BM$18:BM$1048576))-INDEX(BM$18:BM$1048576,COUNTA(BM$18:BM$1048576)-12)} -> -1.3558826
A8: Change since Covid (Dec 19-feb 20) | B8: {=INDEX(B$18:B$1048576,COUNTA(B$18:B$1048576))-B$351} -> 1045032 | C8: {=INDEX(C$18:C$1048576,COUNTA(C$18:C$1048576))-C$351} -> -1.3296027 | D8: {=INDEX(D$18:D$1048576,COUNTA(D$18:D$1048576))-D$351} -> 468168.17 | E8: {=INDEX(E$18:E$1048576,COUNTA(E$18:E$1048576))-E$351} -> 1.1327015 | F8: {=INDEX(F$18:F$1048576,COUNTA(F$18:F$1048576))-F$351} -> 1513200.2 | G8: {=INDEX(G$18:G$1048576,COUNTA(G$18:G$1048576))-G$351} -> -0.63025449 | H8: {=INDEX(H$18:H$1048576,COUNTA(H$18:H$1048576))-H$351} -> 1380838.8 | I8: {=INDEX(I$18:I$1048576,COUNTA(I$18:I$1048576))-I$351} -> 0.63025449 | ... BM8: {=INDEX(BM$18:BM$1048576,COUNTA(BM$18:BM$1048576))-BM$351} -> -2.0105074
A9: change since 2010 election | B9: {=INDEX(B$18:B$1048576,COUNTA(B$18:B$1048576))-B$233} -> 5178741.8 | C9: {=INDEX(C$18:C$1048576,COUNTA(C$18:C$1048576))-C$233} -> 2.6872425 | D9: {=INDEX(D$18:D$1048576,COUNTA(D$18:D$1048576))-D$233} -> -677652.17 | E9: {=INDEX(E$18:E$1048576,COUNTA(E$18:E$1048576))-E$233} -> -2.8720093 | F9: {=INDEX(F$18:F$1048576,COUNTA(F$18:F$1048576))-F$233} -> 4501089.6 | G9: {=INDEX(G$18:G$1048576,COUNTA(G$18:G$1048576))-G$233} -> 0.9244481 | H9: {=INDEX(H$18:H$1048576,COUNTA(H$18:H$1048576))-H$233} -> 1814587.4 | I9: {=INDEX(I$18:I$1048576,COUNTA(I$18:I$1048576))-I$233} -> -0.9244481 | ... BM9: {=INDEX(BM$18:BM$1048576,COUNTA(BM$18:BM$1048576))-BM$233} -> -5.4555123
A10: change since 2024 election | B10: {=INDEX(B$18:B$1048576,COUNTA(B$18:B$1048576))-B$403} -> 737154.92 | C10: {=INDEX(C$18:C$1048576,COUNTA(C$18:C$1048576))-C$403} -> 0.47639709 | D10: {=INDEX(D$18:D$1048576,COUNTA(D$18:D$1048576))-D$403} -> 365071.28 | E10: {=INDEX(E$18:E$1048576,COUNTA(E$18:E$1048576))-E$403} -> 0.88418044 | F10: {=INDEX(F$18:F$1048576,COUNTA(F$18:F$1048576))-F$403} -> 1102226.2 | G10: {=INDEX(G$18:G$1048576,COUNTA(G$18:G$1048576))-G$403} -> 1.0873532 | H10: {=INDEX(H$18:H$1048576,COUNTA(H$18:H$1048576))-H$403} -> -324180.19 | I10: {=INDEX(I$18:I$1048576,COUNTA(I$18:I$1048576))-I$403} -> -1.0873532 | ... BM10: {=INDEX(BM$18:BM$1048576,COUNTA(BM$18:BM$1048576))-BM$403} -> -1.746035
A11: Table 2: Labour market activity by age group (seasonally adjusted) | J11: =J418-J402 -> 624421.87
A12: Date of publication: | B12: 45335 | G12: Date of next publication: | J12: 45363 | M12: Source: Labour Force Survey
A13: Inquiries: Email: | B13: labour.market@ons.gov.uk | G13: Tel: 01633 455400 | J13: =K414-K417 -> 0.17762781
A14: United Kingdom (thousands) seasonally adjusted
B15: Aged 16 and over | J15: Aged 16-64 | R15: Aged 16-17 | Z15: Aged 18-24 | AH15: Aged 25-34 | AP15: Aged 35-49 | AX15: Aged 50-64 | BF15: Age 65+
B16: Employment | D16: Unemployment | F16: Activity | H16: Inactivity | J16: Employment | L16: Unemployment | N16: Activity | P16: Inactivity | R16: Employment | T16: Unemployment | V16: Activity | X16: Inactivity | Z16: Employment | AB16: Unemployment | AD16: Activity | AF16: Inactivity | AH16: Employment | AJ16: Unemployment | AL16: Activity | AN16: Inactivity | AP16: Employment | AR16: Unemployment | AT16: Activity | AV16: Inactivity | AX16: Employment | AZ16: Unemployment | BB16: Activity | BD16: Inactivity | BF16: Employment | BH16: Unemployment | BJ16: Activity | BL16: Inactivity
B17: level | C17: rate (%) | D17: level | E17: rate (%) | F17: level | G17: rate (%) | H17: level | I17: rate (%) | J17: level | K17: rate (%) | L17: level | M17: rate (%) | N17: level | O17: rate (%) | P17: level | Q17: rate (%) | R17: level | S17: rate (%) | T17: level | U17: rate (%) | V17: level | W17: rate (%) | X17: level | Y17: rate (%) | Z17: level | AA17: rate (%) | AB17: level | AC17: rate (%) | AD17: level | AE17: rate (%) | AF17: level | AG17: rate (%) | AH17: level | AI17: rate (%) | AJ17: level | AK17: rate (%) | AL17: level | AM17: rate (%) | AN17: level | AO17: rate (%) | AP17: level | AQ17: rate (%) | AR17: level | AS17: rate (%) | AT17: level | AU17: rate (%) | AV17: level | AW17: rate (%) | AX17: level | AY17: rate (%) | AZ17: level | BA17: rate (%) | BB17: level | BC17: rate (%) | BD17: level | BE17: rate (%) | BF17: level | BG17: rate (%) | BH17: level | BI17: rate (%) | BJ17: level | BK17: rate (%) | BL17: level | BM17: rate (%)
A18: Mar-May 1992 | B18: 25635937 | C18: 56.978873 | D18: 2795738.4 | E18: 9.8331819 | F18: 28431675 | G18: 63.19273 | H18: 16560329 | I18: 36.80727 | J18: 25157591 | K18: 69.194504 | L18: 2771842.3 | M18: 9.9244488 | N18: 27929433 | O18: 76.818297 | P18: 8428354.6 | Q18: 23.181703 | R18: 672842.98 | S18: 48.815635 | T18: 148298.6 | U18: 18.060053 | V18: 821141.59 | W18: 59.574892 | X18: 557193.41 | Y18: 40.425108 | Z18: 3807969.1 | AA18: 65.851182 | AB18: 711645.67 | AC18: 15.745715 | AD18: 4519614.8 | AE18: 78.157666 | AF18: 1263074.2 | AG18: 21.842334 | AH18: 6569245 | AI18: 73.761625 | AJ18: 766486.76 | AK18: 10.448675 | AL18: 7335731.8 | AM18: 82.367988 | AN18: 1570315.2 | AO18: 17.632012 | AP18: 9130969.3 | AQ18: 79.563995 | AR18: 715160.37 | AS18: 7.2633653 | AT18: 9846129.7 | AU18: 85.795646 | AV18: 1630128.3 | AW18: 14.204354 | AX18: 4976564.7 | AY18: 56.459105 | AZ18: 430250.91 | BA18: 7.9575657 | BB18: 5406815.6 | BC18: 61.3403 | BD18: 3407643.4 | BE18: 38.6597 | BF18: 478345.94 | BG18: 5.5401202 | BH18: 23896.055 | BI18: 4.7578768 | BJ18: 502242 | BK18: 5.8168802 | BL18: 8131974 | BM18: 94.18312
A19: Apr-Jun 1992 | B19: 25605421 | C19: 56.906189 | D19: 2777367.7 | E19: 9.785394 | F19: 28382788 | G19: 63.078687 | H19: 16613057 | I19: 36.921313 | J19: 25121755 | K19: 69.095274 | L19: 2755380.3 | M19: 9.8840153 | N19: 27877135 | O19: 76.673716 | P19: 8481002.7 | Q19: 23.326284 | R19: 664951.75 | S19: 48.404968 | T19: 154422.9 | U19: 18.846433 | V19: 819374.64 | W19: 59.646137 | X19: 554351.61 | Y19: 40.353863 | Z19: 3773820.3 | AA19: 65.44936 | AB19: 703256.67 | AC19: 15.707942 | AD19: 4477077 | AE19: 77.64594 | AF19: 1288938.6 | AG19: 22.35406 | AH19: 6562285.8 | AI19: 73.607934 | AJ19: 774481.14 | AK19: 10.556164 | AL19: 7336767 | AM19: 82.295144 | AN19: 1578421.2 | AO19: 17.704856 | AP19: 9154912.9 | AQ19: 79.688748 | AR19: 691103.96 | AS19: 7.0191223 | AT19: 9846016.8 | AU19: 85.704448 | AV19: 1642321.4 | AW19: 14.295552 | AX19: 4965784.3 | AY19: 56.334176 | AZ19: 432115.65 | BA19: 8.0052549 | BB19: 5397900 | BC19: 61.236297 | BD19: 3416970 | BE19: 38.763703 | BF19: 483665.56 | BG19: 5.5994671 | BH19: 21987.331 | BI19: 4.3483051 | BJ19: 505652.89 | BK19: 5.8540177 | BL19: 8132054 | BM19: 94.145982
A20: May-Jul 1992 | B20: 25541631 | C20: 56.759881 | D20: 2802624.9 | E20: 9.8878055 | F20: 28344256 | G20: 62.988013 | H20: 16655188 | I20: 37.011987 | J20: 25071012 | K20: 68.95567 | L20: 2780378.7 | M20: 9.9829079 | N20: 27851391 | O20: 76.602863 | P20: 8506768.3 | Q20: 23.397137 | R20: 657021.66 | S20: 47.988417 | T20: 160526.33 | U20: 19.635096 | V20: 817547.99 | W20: 59.713152 | X20: 551577.51 | Y20: 40.286848 | Z20: 3732657.6 | AA20: 64.922411 | AB20: 704380.25 | AC20: 15.875011 | AD20: 4437037.9 | AE20: 77.173753 | AF20: 1312375.3 | AG20: 22.826247 | AH20: 6563532.7 | AI20: 73.546748 | AJ20: 774921.42 | AK20: 10.559737 | AL20: 7338454.1 | AM20: 82.230022 | AN20: 1585846.2 | AO20: 17.769978 | AP20: 9147971.3 | AQ20: 79.549054 | AR20: 702795.56 | AS20: 7.1344248 | AT20: 9850766.9 | AU20: 85.660434 | AV20: 1649019.5 | AW20: 14.339566 | AX20: 4969829 | AY20: 56.375814 | AZ20: 437755.16 | BA20: 8.0952074 | BB20: 5407584.2 | BC20: 61.341539 | BD20: 3407949.8 | BE20: 38.658461 | BF20: 470618.68 | BG20: 5.4461656 | BH20: 22246.196 | BI20: 4.51365 | BJ20: 492864.88 | BK20: 5.7036065 | BL20: 8148420 | BM20: 94.296394
A21: Jun-Aug 1992 | B21: 25525070 | C21: 56.721622 | D21: 2816125.8 | E21: 9.9365103 | F21: 28341196 | G21: 62.979596 | H21: 16659404 | I21: 37.020404 | J21: 25060700 | K21: 68.931149 | L21: 2794467.3 | M21: 10.032132 | N21: 27855168 | O21: 76.61752 | P21: 8500965.7 | Q21: 23.38248 | R21: 655096.25 | S21: 48.013865 | T21: 155254.86 | U21: 19.158962 | V21: 810351.11 | W21: 59.392934 | X21: 554038.64 | Y21: 40.607066 | Z21: 3719998.3 | AA21: 64.885011 | AB21: 714329.99 | AC21: 16.109091 | AD21: 4434328.3 | AE21: 77.344508 | AF21: 1298888.4 | AG21: 22.655492 | AH21: 6566665.2 | AI21: 73.542227 | AJ21: 775662.24 | AK21: 10.564256 | AL21: 7342327.5 | AM21: 82.229121 | AN21: 1586781 | AO21: 17.770879 | AP21: 9143812.7 | AQ21: 79.452506 | AR21: 703958.08 | AS21: 7.1484003 | AT21: 9847770.8 | AU21: 85.569345 | AV21: 1660755.7 | AW21: 14.430655 | AX21: 4975128 | AY21: 56.401643 | AZ21: 445262.13 | BA21: 8.2145771 | BB21: 5420390.1 | BC21: 61.449456 | BD21: 3400501.9 | BE21: 38.550544 | BF21: 464369.35 | BG21: 5.3718688 | BH21: 21658.542 | BI21: 4.4562342 | BJ21: 486027.9 | BK21: 5.6224168 | BL21: 8158437.9 | BM21: 94.377583
A22: Jul-Sep 1992 | B22: 25509005 | C22: 56.682283 | D22: 2814524.8 | E22: 9.9370554 | F22: 28323530 | G22: 62.936297 | H22: 16679960 | I22: 37.063703 | J22: 25051022 | K22: 68.904267 | L22: 2793342.4 | M22: 10.031985 | N22: 27844364 | O22: 76.587515 | P22: 8511906.3 | Q22: 23.412485 | R22: 648817.45 | S22: 47.720183 | T22: 146301.37 | U22: 18.399938 | V22: 795118.82 | W22: 58.480572 | X22: 564510.18 | Y22: 41.519428 | Z22: 3700258.4 | AA22: 64.724227 | AB22: 723869.61 | AC22: 16.36186 | AD22: 4424128 | AE22: 77.386019 | AF22: 1292832.3 | AG22: 22.613981 | AH22: 6586437.2 | AI22: 73.720371 | AJ22: 762085.43 | AK22: 10.370594 | AL22: 7348522.7 | AM22: 82.250206 | AN22: 1585829 | AO22: 17.749794 | AP22: 9154876.5 | AQ22: 79.480524 | AR22: 712240.98 | AS22: 7.2183288 | AT22: 9867117.4 | AU22: 85.664036 | AV22: 1651272.2 | AW22: 14.335964 | AX22: 4960632.4 | AY22: 56.198778 | AZ22: 448845.05 | BA22: 8.2973827 | BB22: 5409477.5 | BC22: 61.283723 | BD22: 3417462.5 | BE22: 38.716277 | BF22: 457983.03 | BG22: 5.2963045 | BH22: 21182.41 | BI22: 4.4206882 | BJ22: 479165.44 | BK22: 5.5412666 | BL22: 8168053.2 | BM22: 94.458733
A23: Aug-Oct 1992 | B23: 25454432 | C23: 56.55781 | D23: 2849869.1 | E23: 10.068678 | F23: 28304301 | G23: 62.890002 | H23: 16701741 | I23: 37.109998 | J23: 24999843 | K23: 68.764542 | L23: 2829973 | M23: 10.168853 | N23: 27829816 | O23: 76.548662 | P23: 8525902.4 | Q23: 23.451338 | R23: 628524.21 | S23: 46.391089 | T23: 135175.21 | U23: 17.700054 | V23: 763699.42 | W23: 56.36831 | X23: 591138.83 | Y23: 43.63169 | Z23: 3693704.8 | AA23: 64.794223 | AB23: 740436.82 | AC23: 16.698538 | AD23: 4434141.6 | AE23: 77.782816 | AF23: 1266528.3 | AG23: 22.217184 | AH23: 6575853.7 | AI23: 73.560218 | AJ23: 775080.19 | AK23: 10.543969 | AL23: 7350933.9 | AM23: 82.230585 | AN23: 1588481.9 | AO23: 17.769415 | AP23: 9157510.7 | AQ23: 79.437958 | AR23: 727787.21 | AS23: 7.3623194 | AT23: 9885297.9 | AU23: 85.751238 | AV23: 1642579.9 | AW23: 14.248762 | AX23: 4944250 | AY23: 55.97528 | AZ23: 451493.6 | BA23: 8.3675882 | BB23: 5395743.6 | BC23: 61.086769 | BD23: 3437173.4 | BE23: 38.913231 | BF23: 454588.67 | BG23: 5.2551638 | BH23: 19896.06 | BI23: 4.1931929 | BJ23: 474484.73 | BK23: 5.4851674 | BL23: 8175838.9 | BM23: 94.514833
A24: Sep-Nov 1992 | B24: 25406419 | C24: 56.449606 | D24: 2898811.3 | E24: 10.241257 | F24: 28305230 | G24: 62.890371 | H24: 16702026 | I24: 37.109629 | J24: 24962923 | K24: 68.666128 | L24: 2880096.3 | M24: 10.344052 | N24: 27843020 | O24: 76.58848 | P24: 8511037.4 | Q24: 23.41152 | R24: 623263.78 | S24: 46.162438 | T24: 136924.83 | U24: 18.011955 | V24: 760188.61 | W24: 56.303865 | X24: 589964.89 | Y24: 43.696135 | Z24: 3682050 | AA24: 64.774538 | AB24: 750677.65 | AC24: 16.934892 | AD24: 4432727.6 | AE24: 77.980442 | AF24: 1251681.9 | AG24: 22.019558 | AH24: 6571774.9 | AI24: 73.47512 | AJ24: 787965.68 | AK24: 10.706433 | AL24: 7359740.6 | AM24: 82.284897 | AN24: 1584477.4 | AO24: 17.715103 | AP24: 9161864.5 | AQ24: 79.415391 | AR24: 730505.38 | AS24: 7.3845336 | AT24: 9892369.9 | AU24: 85.747439 | AV24: 1644266.1 | AW24: 14.252561 | AX24: 4923970.1 | AY24: 55.70959 | AZ24: 474022.79 | BA24: 8.7814639 | BB24: 5397992.9 | BC24: 61.072664 | BD24: 3440647.1 | BE24: 38.927336 | BF24: 443495.8 | BG24: 5.1252233 | BH24: 18714.996 | BI24: 4.0490174 | BJ24: 462210.8 | BK24: 5.3415017 | BL24: 8190988.7 | BM24: 94.658498
A25: Oct-Dec 1992 | B25: 25335708 | C25: 56.289377 | D25: 2931640.3 | E25: 10.371119 | F25: 28267348 | G25: 62.802722 | H25: 16742402 | I25: 37.197278 | J25: 24904858 | K25: 68.507651 | L25: 2912254.2 | M25: 10.46929 | N25: 27817112 | O25: 76.518606 | P25: 8536284.2 | Q25: 23.481394 | R25: 613179.3 | S25: 45.576197 | T25: 143304.85 | U25: 18.943537 | V25: 756484.15 | W25: 56.227714 | X25: 588909.6 | Y25: 43.772286 | Z25: 3657106.4 | AA25: 64.520168 | AB25: 749834.88 | AC25: 17.01486 | AD25: 4406941.3 | AE25: 77.749062 | AF25: 1261218.8 | AG25: 22.250938 | AH25: 6566330.4 | AI25: 73.371467 | AJ25: 796807.58 | AK25: 10.821576 | AL25: 7363138 | AM25: 82.274909 | AN25: 1586295.1 | AO25: 17.725091 | AP25: 9151189.4 | AQ25: 79.257564 | AR25: 741700.09 | AS25: 7.4973049 | AT25: 9892889.5 | AU25: 85.681356 | AV25: 1653250.7 | AW25: 14.318644 | AX25: 4917052.2 | AY25: 55.595914 | AZ25: 480606.78 | BA25: 8.9039856 | BB25: 5397659 | BC25: 61.030018 | BD25: 3446610 | BE25: 38.969982 | BF25: 430849.95 | BG25: 4.9772685 | BH25: 19386.125 | BI25: 4.3057689 | BJ25: 450236.08 | BK25: 5.2012211 | BL25: 8206117.3 | BM25: 94.798779
A26: Nov-Jan 1993 | B26: 25301164 | C26: 56.210098 | D26: 2982756.3 | E26: 10.545767 | F26: 28283920 | G26: 62.836711 | H26: 16727857 | I26: 37.163289 | J26: 24869383 | K26: 68.411497 | L26: 2964559.6 | M26: 10.650879 | N26: 27833942 | O26: 76.566503 | P26: 8518694 | Q26: 23.433497 | R26: 601737.22 | S26: 44.888946 | T26: 148625.82 | U26: 19.807188 | V26: 750363.04 | W26: 55.976271 | X26: 590138.96 | Y26: 44.023729 | Z26: 3642900.1 | AA26: 64.453285 | AB26: 758732.77 | AC26: 17.23753 | AD26: 4401632.8 | AE26: 77.87743 | AF26: 1250367.8 | AG26: 22.12257 | AH26: 6577421.7 | AI26: 73.455902 | AJ26: 802411.97 | AK26: 10.873036 | AL26: 7379833.7 | AM26: 82.417149 | AN26: 1574411.7 | AO26: 17.582851 | AP26: 9134290.6 | AQ26: 79.048594 | AR26: 755263.86 | AS26: 7.6369857 | AT26: 9889554.5 | AU26: 85.584684 | AV26: 1665730.9 | AW26: 14.415316 | AX26: 4913033.1 | AY26: 55.510717 | AZ26: 499525.19 | BA26: 9.2290034 | BB26: 5412558.3 | BC26: 61.154684 | BD26: 3438044.7 | BE26: 38.845316 | BF26: 431780.84 | BG26: 4.986417 | BH26: 18196.685 | BI26: 4.0439097 | BJ26: 449977.53 | BK26: 5.1965612 | BL26: 8209162.8 | BM26: 94.803439
A27: Dec-Feb 1993 | B27: 25274286 | C27: 56.147416 | D27: 3023283.2 | E27: 10.683897 | F27: 28297569 | G27: 62.86371 | H27: 16716588 | I27: 37.13629 | J27: 24839004 | K27: 68.329654 | L27: 3005600.8 | M27: 10.794194 | N27: 27844605 | O27: 76.597766 | P27: 8507114.4 | Q27: 23.402234 | R27: 589709.19 | S27: 44.1438 | T27: 147847.45 | U27: 20.045572 | V27: 737556.64 | W27: 55.211201 | X27: 598325.61 | Y27: 44.788799 | Z27: 3626688.4 | AA27: 64.350812 | AB27: 774878.08 | AC27: 17.604598 | AD27: 4401566.4 | AE27: 78.100004 | AF27: 1234241.8 | AG27: 21.899996 | AH27: 6573950.2 | AI27: 73.372982 | AJ27: 815460.81 | AK27: 11.035532 | AL27: 7389411.1 | AM27: 82.474479 | AN27: 1570222.4 | AO27: 17.525521 | AP27: 9123860.8 | AQ27: 78.895396 | AR27: 770251.41 | AS27: 7.7849472 | AT27: 9894112.2 | AU27: 85.555876 | AV27: 1670391.3 | AW27: 14.444124 | AX27: 4924795.6 | AY27: 55.610385 | AZ27: 497163.07 | BA27: 9.1694367 | BB27: 5421958.7 | BC27: 61.224309 | BD27: 3433933.3 | BE27: 38.775691 | BF27: 435281.59 | BG27: 5.0249321 | BH27: 17682.355 | BI27: 3.9037004 | BJ27: 452963.95 | BK27: 5.2290589 | BL27: 8209473.3 | BM27: 94.770941
A28: Jan-Mar 1993 | B28: 25282289 | C28: 56.163389 | D28: 3003526.8 | E28: 10.618491 | F28: 28285816 | G28: 62.835579 | H28: 16729789 | I28: 37.164421 | J28: 24847113 | K28: 68.354168 | L28: 2984739.8 | M28: 10.724187 | N28: 27831853 | O28: 76.565158 | P28: 8518692.9 | Q28: 23.434842 | R28: 587790.99 | S28: 44.156249 | T28: 143512.75 | U28: 19.624233 | V28: 731303.73 | W28: 54.937266 | X28: 599857.77 | Y28: 45.062734 | Z28: 3602671.5 | AA28: 64.109929 | AB28: 780912.52 | AC28: 17.814476 | AD28: 4383584 | AE28: 78.006352 | AF28: 1235937.9 | AG28: 21.993648 | AH28: 6591842.4 | AI28: 73.534333 | AJ28: 802247.85 | AK28: 10.849852 | AL28: 7394090.2 | AM28: 82.483692 | AN28: 1570215.4 | AO28: 17.516308 | AP28: 9128037.7 | AQ28: 78.867686 | AR28: 765601.85 | AS28: 7.7383237 | AT28: 9893639.6 | AU28: 85.482607 | AV28: 1680223.1 | AW28: 14.517393 | AX28: 4936770.4 | AY28: 55.709105 | AZ28: 492464.82 | BA28: 9.0706112 | BB28: 5429235.2 | BC28: 61.266336 | BD28: 3432458.8 | BE28: 38.733664 | BF28: 435176.21 | BG28: 5.0221955 | BH28: 18787.035 | BI28: 4.1384485 | BJ28: 453963.25 | BK28: 5.2390092 | BL28: 8211095.9 | BM28: 94.760991
A29: Feb-Apr 1993 | B29: 25258217 | C29: 56.10629 | D29: 2988474.6 | E29: 10.57991 | F29: 28246692 | G29: 62.744614 | H29: 16771821 | I29: 37.255386 | J29: 24824126 | K29: 68.291867 | L29: 2969360.9 | M29: 10.683657 | N29: 27793487 | O29: 76.460663 | P29: 8556560.4 | Q29: 23.539337 | R29: 576754.25 | S29: 43.483966 | T29: 140457.66 | U29: 19.583843 | V29: 717211.91 | W29: 54.073668 | X29: 609148.84 | Y29: 45.926332 | Z29: 3566918.9 | AA29: 63.657292 | AB29: 773854.39 | AC29: 17.82757 | AD29: 4340773.2 | AE29: 77.467944 | AF29: 1262542.2 | AG29: 22.532056 | AH29: 6606869.8 | AI29: 73.659732 | AJ29: 795947.06 | AK29: 10.751949 | AL29: 7402816.9 | AM29: 82.533715 | AN29: 1566629 | AO29: 17.466285 | AP29: 9125446.4 | AQ29: 78.780012 | AR29: 765785.88 | AS29: 7.7420675 | AT29: 9891232.3 | AU29: 85.391045 | AV29: 1692221.6 | AW29: 14.608955 | AX29: 4948137.2 | AY29: 55.80099 | AZ29: 493315.96 | BA29: 9.0658864 | BB29: 5441453.1 | BC29: 61.364199 | BD29: 3426018.9 | BE29: 38.635801 | BF29: 434090.92 | BG29: 5.0077023 | BH29: 19113.649 | BI29: 4.2174439 | BJ29: 453204.57 | BK29: 5.2281986 | BL29: 8215260.5 | BM29: 94.771801
... A419: Aug-Oct 2025 | B419: 34226340 | C419: 60.689871 | D419: 1831890.1 | E419: 5.0803661 | F419: 36058230 | G419: 63.938164 | H419: 20337243 | I419: 36.061836 | J419: 32486778 | K419: 74.915831 | L419: 1778933.7 | M419: 5.1915854 | N419: 34265712 | O419: 79.018124 | P419: 9098658.3 | Q419: 20.981876 | R419: 325541.93 | S419: 19.941936 | T419: 188250.06 | U419: 36.639353 | V419: 513792 | W419: 31.473694 | X419: 1118657 | Y419: 68.526306 | Z419: 3529344.5 | AA419: 60.507243 | AB419: 546361.34 | AC419: 13.405318 | AD419: 4075705.9 | AE419: 69.874087 | AF419: 1757223.1 | AG419: 30.125913 | AH419: 7675153.9 | AI419: 83.820727 | AJ419: 368725.43 | AK419: 4.5839255 | AL419: 8043879.3 | AM419: 87.847596 | AN419: 1112750.7 | AO419: 12.152404 | AP419: 11485218 | AQ419: 85.005301 | AR419: 373494.6 | AS419: 3.1495374 | AT419: 11858713 | AU419: 87.769639 | AV419: 1652466 | AW419: 12.230361 | AX419: 9471519.2 | AY419: 71.584825 | AZ419: 302102.23 | BA419: 3.0909958 | BB419: 9773621.5 | BC419: 73.868085 | BD419: 3457561.5 | BE419: 26.131915 | BF419: 1739561.9 | BG419: 13.349306 | BH419: 52956.431 | BI419: 2.9543035 | BJ419: 1792518.3 | BK419: 13.755691 | BL419: 11238585 | BM419: 86.244309
AC420: =AC418-AC406 -> -0.92378111
A421: Quality indicator | AC421: =AC418-AC415 -> 0.6717654
A422: Shaded estimates are based on a small sample size. This may result in less precise estimates, which should be used with caution.
A423: Unshaded estimates are based on a larger sample size. This is likely to result in estimates of higher precision, although they will still be subject to some sampling variability.
A424: * Estimate has been suppressed on disclosure grounds.

Sheet 5
B2: Workforce jobs | C2: Employee jobs | D2: Self-employment jobs | E2: HM Forces | F2: Government- supported trainees
A3: Current | B3: {=INDEX(B$16:B$1048576,COUNTA(B$16:B$1048576))} -> 36557 | C3: {=INDEX(C$16:C$1048576,COUNTA(C$16:C$1048576))} -> 32291 | D3: {=INDEX(D$16:D$1048576,COUNTA(D$16:D$1048576))} -> 4066 | E3: {=INDEX(E$16:E$1048576,COUNTA(E$16:E$1048576))} -> 148 | F3: {=INDEX(F$16:F$1048576,COUNTA(F$16:F$1048576))} -> 52
A4: Quarterly change | B4: {=INDEX(B$16:B$1048576,COUNTA(B$16:B$1048576))-INDEX(B$16:B$1048576,COUNTA(B$16:B$1048576)-1)} -> -116 | C4: {=INDEX(C$16:C$1048576,COUNTA(C$16:C$1048576))-INDEX(C$16:C$1048576,COUNTA(C$16:C$1048576)-1)} -> -15 | D4: {=INDEX(D$16:D$1048576,COUNTA(D$16:D$1048576))-INDEX(D$16:D$1048576,COUNTA(D$16:D$1048576)-1)} -> -120 | E4: {=INDEX(E$16:E$1048576,COUNTA(E$16:E$1048576))-INDEX(E$16:E$1048576,COUNTA(E$16:E$1048576)-1)} -> 1 | F4: {=INDEX(F$16:F$1048576,COUNTA(F$16:F$1048576))-INDEX(F$16:F$1048576,COUNTA(F$16:F$1048576)-1)} -> 18
A5: Max | B5: =MAX(B$16:B$1048576) -> 36931 | C5: =MAX(C$16:C$1048576) -> 32388 | D5: =MAX(D$16:D$1048576) -> 4693 | E5: =MAX(E$16:E$1048576) -> 595 | F5: =MAX(F$16:F$1048576) -> 467
A6: Jobs created since new gov | B6: {=INDEX(B$16:B$1048576,COUNTA(B$16:B$1048576))-B$276} -> -78 | C6: {=INDEX(C$16:C$1048576,COUNTA(C$16:C$1048576))-C$276} -> 75 | D6: {=INDEX(D$16:D$1048576,COUNTA(D$16:D$1048576))-D$276} -> -170 | E6: {=INDEX(E$16:E$1048576,COUNTA(E$16:E$1048576))-E$276} -> -1 | F6: {=INDEX(F$16:F$1048576,COUNTA(F$16:F$1048576))-F$276} -> 18
A8: Table 5: Workforce jobs (seasonally adjusted)1
A9: Date of publication: | C9: 45916 | E9: Date of next publication: | F9: 46007
A10: Inquiries: Email: | C10: workforce.jobs@ons.gov.uk | E10: Telephone: | F10: 01633 455400
F11: Sources: Employer surveys, Labour Force Survey and administrative sources
A12: United Kingdom (thousands) seasonally adjusted
B13: Workforce jobs1 | C13: Employee jobs1 | D13: Self-employment jobs2 | E13: HM Forces | F13: Government- supported trainees2 3
B14: 1 | C14: 2 | D14: 3 | E14: 4 | F14: 5
B15: DYDC | C15: BCAJ | D15: DYZN | E15: LOJX | F15: LOJU
A16: Jun 59 | B16: 25555 | C16: 23125 | D16: 1835 | E16: 595 | F16: 0
A17: Sep 59 | B17: 25660 | C17: 23248 | D17: 1834 | E17: 577 | F17: 0
A18: Dec 59 | B18: 25751 | C18: 23370 | D18: 1820 | E18: 560 | F18: 0
A19: Mar 60 | B19: 25905 | C19: 23531 | D19: 1824 | E19: 550 | F19: 0
A20: Jun 60 | B20: 26015 | C20: 23634 | D20: 1840 | E20: 541 | F20: 0
A21: Sep 60 | B21: 26060 | C21: 23685 | D21: 1839 | E21: 536 | F21: 0
A22: Dec 60 | B22: 26246 | C22: 23894 | D22: 1827 | E22: 526 | F22: 0
A23: Mar 61 | B23: 26345 | C23: 24011 | D23: 1827 | E23: 507 | F23: 0
A24: Jun 61 | B24: 26312 | C24: 23985 | D24: 1832 | E24: 495 | F24: 0
A25: Sep 61 | B25: 26374 | C25: 24065 | D25: 1824 | E25: 485 | F25: 0
A26: Dec 61 | B26: 26301 | C26: 24014 | D26: 1812 | E26: 475 | F26: 0
A27: Mar 62 | B27: 26450 | C27: 24175 | D27: 1809 | E27: 466 | F27: 0
... A274: Dec 23 (r) | B274: 36470 | C274: 32144 | D274: 4137 | E274: 151 | F274: 38
A275: Mar 24 (r) | B275: 36711 | C275: 32203 | D275: 4329 | E275: 148 | F275: 31 | G275: 1
A276: Jun 24 (r) | B276: 36635 | C276: 32216 | D276: 4236 | E276: 149 | F276: 34 | G276: 1
A277: Sep 24 (r) | B277: 36672 | C277: 32216 | D277: 4266 | E277: 148 | F277: 42
A278: Dec 24 (r) | B278: 36829 | C278: 32348 | D278: 4279 | E278: 147 | F278: 55
A279: Mar 25 (r) | B279: 36931 | C279: 32388 | D279: 4342 | E279: 148 | F279: 53
A280: Jun 25 (r) | B280: 36673 | C280: 32306 | D280: 4186 | E280: 147 | F280: 34 | H280: =B280-B276 -> 38
A281: Sep 25 (p) | B281: 36557 | C281: 32291 | D281: 4066 | E281: 148 | F281: 52
A282: 2. Workforce Jobs figures are a measure of jobs rather than people. For this reason estimates of self-employment jobs and government supported trainee jobs differ from estimates of people in self-employment and in government supported training and employment programmes. The estimates for government supported trainees shown in this table exclude trainees with contracts of employment as such people are included in the estimates of employee jobs. | G282: =B280-B276 -> 38
A283: 3. Due to a change in the method of compiling the data, there is currently a discontinuity between June and September 2002. These estimates do not include jobs with a contract of employment as such jobs are recorded in the employee jobs series.
A284: 4. The employee jobs data relate to the March 2020 period before reported cases of the coronavirus (COVID-19) in the UK. Self-employment jobs relate to the period February-April 2020 which includes self-employment jobs before and after COVID-19 measures were implemented .
A285: 5. Data for September 2022 onwards, for workforce jobs, self-employment jobs, government supported trainees and in SIC 2007 divisions 01 and 97-98 of employee jobs, has been affected by the reweighting of the LFS, causing a step change discontinuity.

Sheet 10
B1: People | D1: Men | F1: Women
B2: Level1 | C2: Rate per thousand2 | D2: Level1 | E2: Rate per thousand2 | F2: Level1 | G2: Rate per thousand2
A3: Current | B3: {=INDEX(B$18:B$1048576,COUNTA(B$18:B$1048576))} -> 156239 | C3: {=INDEX(C$18:C$1048576,COUNTA(C$18:C$1048576))} -> 5.2700935 | D3: {=INDEX(D$18:D$1048576,COUNTA(D$18:D$1048576))} -> 89850 | E3: {=INDEX(E$18:E$1048576,COUNTA(E$18:E$1048576))} -> 6.0970633 | F3: {=INDEX(F$18:F$1048576,COUNTA(F$18:F$1048576))} -> 66389 | G3: {=INDEX(G$18:G$1048576,COUNTA(G$18:G$1048576))} -> 4.4527267
A4: Quarterly change | B4: {=INDEX(B$18:B$1048576,COUNTA(B$18:B$1048576))-INDEX(B$18:B$1048576,COUNTA(B$18:B$1048576)-3)} -> 51943 | C4: {=INDEX(C$18:C$1048576,COUNTA(C$18:C$1048576))-INDEX(C$18:C$1048576,COUNTA(C$18:C$1048576)-3)} -> 1.7264944 | D4: {=INDEX(D$18:D$1048576,COUNTA(D$18:D$1048576))-INDEX(D$18:D$1048576,COUNTA(D$18:D$1048576)-3)} -> 33820 | E4: {=INDEX(E$18:E$1048576,COUNTA(E$18:E$1048576))-INDEX(E$18:E$1048576,COUNTA(E$18:E$1048576)-3)} -> 2.2583539 | F4: {=INDEX(F$18:F$1048576,COUNTA(F$18:F$1048576))-INDEX(F$18:F$1048576,COUNTA(F$18:F$1048576)-3)} -> 18123 | G4: {=INDEX(G$18:G$1048576,COUNTA(G$18:G$1048576))-INDEX(G$18:G$1048576,COUNTA(G$18:G$1048576)-3)} -> 1.1994616
A5: year on year change | B5: {=INDEX(B$18:B$1048576,COUNTA(B$18:B$1048576))-INDEX(B$18:B$1048576,COUNTA(B$18:B$1048576)-12)} -> 57485 | C5: {=INDEX(C$18:C$1048576,COUNTA(C$18:C$1048576))-INDEX(C$18:C$1048576,COUNTA(C$18:C$1048576)-12)} -> 1.8796563 | D5: {=INDEX(D$18:D$1048576,COUNTA(D$18:D$1048576))-INDEX(D$18:D$1048576,COUNTA(D$18:D$1048576)-12)} -> 29398 | E5: {=INDEX(E$18:E$1048576,COUNTA(E$18:E$1048576))-INDEX(E$18:E$1048576,COUNTA(E$18:E$1048576)-12)} -> 1.8999666 | F5: {=INDEX(F$18:F$1048576,COUNTA(F$18:F$1048576))-INDEX(F$18:F$1048576,COUNTA(F$18:F$1048576)-12)} -> 28087 | G5: {=INDEX(G$18:G$1048576,COUNTA(G$18:G$1048576))-INDEX(G$18:G$1048576,COUNTA(G$18:G$1048576)-12)} -> 1.8513827
A6: Since pandemic | B6: {=INDEX(B$18:B$1048576,COUNTA(B$18:B$1048576))-B$351} -> 49226 | C6: {=INDEX(C$18:C$1048576,COUNTA(C$18:C$1048576))-C$351} -> 1.4237069 | D6: {=INDEX(D$18:D$1048576,COUNTA(D$18:D$1048576))-D$351} -> 31966 | E6: {=INDEX(E$18:E$1048576,COUNTA(E$18:E$1048576))-E$351} -> 1.8926884 | F6: {=INDEX(F$18:F$1048576,COUNTA(F$18:F$1048576))-F$351} -> 17260 | G6: {=INDEX(G$18:G$1048576,COUNTA(G$18:G$1048576))-G$351} -> 0.95702903
A7: Since 2010 election | B7: {=INDEX(B$18:B$1048576,COUNTA(B$18:B$1048576))-B$233} -> -16419 | C7: {=INDEX(C$18:C$1048576,COUNTA(C$18:C$1048576))-C$233} -> -1.6509949 | D7: {=INDEX(D$18:D$1048576,COUNTA(D$18:D$1048576))-D$233} -> -28786 | E7: {=INDEX(E$18:E$1048576,COUNTA(E$18:E$1048576))-E$233} -> -3.3650026 | F7: {=INDEX(F$18:F$1048576,COUNTA(F$18:F$1048576))-F$233} -> 12367 | G7: {=INDEX(G$18:G$1048576,COUNTA(G$18:G$1048576))-G$233} -> 0.099129394
A9: Table 10: Redundancies levels1 and rates2 for those aged 16 and over
A10: Date of publication: | B10: 45643 | G10: Date of next publication: | I10: 45678
A11: Inquiries: Email: | B11: labour.market@ons.gov.uk | F11: Tel: 01633 455400 | H11: Source: Labour Force Survey
A12: United Kingdom (thousands)
B13: People | D13: Men | F13: Women
B15: Level1 | C15: Rate per thousand2 | D15: Level1 | E15: Rate per thousand2 | F15: Level1 | G15: Rate per thousand2
A16: Dataset identifier code | B16: BEAO | C16: BEIR | D16: BEIU | E16: BEIX | F16: BEJA | G16: BEJD
A18: Mar-May 1992 | B18: .. | C18: .. | D18: .. | E18: .. | F18: .. | G18: ..
A19: Apr-Jun 1992 | B19: .. | C19: .. | D19: .. | E19: .. | F19: .. | G19: ..
A20: May-Jul 1992 | B20: .. | C20: .. | D20: .. | E20: .. | F20: .. | G20: ..
A21: Jun-Aug 1992 | B21: .. | C21: .. | D21: .. | E21: .. | F21: .. | G21: ..
A22: Jul-Sep 1992 | B22: .. | C22: .. | D22: .. | E22: .. | F22: .. | G22: ..
A23: Aug-Oct 1992 | B23: .. | C23: .. | D23: .. | E23: .. | F23: .. | G23: ..
A24: Sep-Nov 1992 | B24: .. | C24: .. | D24: .. | E24: .. | F24: .. | G24: ..
A25: Oct-Dec 1992 | B25: .. | C25: .. | D25: .. | E25: .. | F25: .. | G25: ..
A26: Nov-Jan 1993 | B26: .. | C26: .. | D26: .. | E26: .. | F26: .. | G26: ..
A27: Dec-Feb 1993 | B27: .. | C27: .. | D27: .. | E27: .. | F27: .. | G27: ..
A28: Jan-Mar 1993 | B28: .. | C28: .. | D28: .. | E28: .. | F28: .. | G28: ..
... A53: Feb-Apr 1995 | B53: .. | C53: .. | D53: .. | E53: .. | F53: .. | G53: ..
A54: Mar-May 1995 | B54: 178580 | C54: 8.251544 | D54: 110631 | E54: 9.9189782 | F54: 67949 | G54: 6.4784023
A55: Apr-Jun 1995 | B55: 178249 | C55: 8.2250899 | D55: 109540 | E55: 9.8141913 | F55: 68709 | G55: 6.5374969
A56: May-Jul 1995 | B56: 168000 | C56: 7.7329073 | D56: 103867 | E56: 9.2790908 | F56: 64133 | G56: 6.0895355
A57: Jun-Aug 1995 | B57: 163905 | C57: 7.5347454 | D57: 104365 | E57: 9.2990437 | F57: 59540 | G57: 5.6543068
A58: Jul-Sep 1995 | B58: 164420 | C58: 7.5466264 | D58: 105296 | E58: 9.3726495 | F58: 59124 | G58: 5.6026685
A59: Aug-Oct 1995 | B59: 166301 | C59: 7.614352 | D59: 109483 | E59: 9.7290985 | F59: 56818 | G59: 5.3666099
A60: Sep-Nov 1995 | B60: 172777 | C60: 7.8856048 | D60: 110607 | E60: 9.7931999 | F60: 62170 | G60: 5.8561635
A61: Oct-Dec 1995 | B61: 162067 | C61: 7.3918845 | D61: 105156 | E61: 9.3096925 | F61: 56911 | G61: 5.353978
A62: Nov-Jan 1996 | B62: 179069 | C62: 8.1652749 | D62: 118724 | E62: 10.525961 | F62: 60345 | G62: 5.6654558
A63: Dec-Feb 1996 | B63: 181867 | C63: 8.2774116 | D63: 119522 | E63: 10.572536 | F63: 62345 | G63: 5.8449181
A64: Jan-Mar 1996 | B64: 195674 | C64: 8.866101 | D64: 130879 | E64: 11.520213 | F64: 64795 | G64: 6.0504675
A65: Feb-Apr 1996 | B65: 180895 | C65: 8.1844071 | D65: 118927 | E65: 10.471299 | F65: 61968 | G65: 5.7671641
... A407: Aug-Oct 2024 | B407: 98754 | C407: 3.3904372 | D407: 60452 | E407: 4.1970967 | F407: 38302 | G407: 2.601344
A408: Sep-Nov 2024 | B408: 111553 | C408: 3.8061282 | D408: 69339 | E408: 4.7764719 | F408: 42214 | G408: 2.8538389 | L408: =AVERAGE(C340:C350) -> 3.8945596
...

Sheet 11
C1: Economic inactivity by reason (thousands) | M1: Percentage of economically inactive (%) | W1: Economic inactivity by wants a job (thousands) | AD1: Percentage of economically inactive by wants a job (%) | AK1: Economic inactivity by does not want a job (thousands) | AR1: Percentage of economically inactive by does not want a job (%)
B2: Total economically inactive aged 16-64 (thousands)4 | C2: Student | D2: Looking after family / home | E2: Temp sick | F2: Long-term sick | G2: Discouraged workers1 | H2: Retired | I2: Other2 | J2: Does not want job (thousands) | K2: Wants a job (thousands) | L2: Total economically inactive aged 16-64 | M2: Student | N2: Looking after family / home | O2: Temp sick | P2: Long-term sick | Q2: Discouraged workers1 | R2: Retired | S2: Other2 | T2: Does not want job (%age of economically inactive) | U2: Wants a job (%age of economically inactive) | V2: Total economically inactive wants a job aged 16-64 (thousands) | W2: Student | X2: Looking after family / home | Y2: Temp sick | Z2: Long-term sick | AA2: Discouraged workers1 | AB2: Other2 | AC2: Total wants a job aged 16-64 | AD2: Student | AE2: Looking after family / home | AF2: Temp sick | AG2: Long-term sick | AH2: Discouraged workers1 | AI2: Other2 | AJ2: Total economically inactive does not want a job aged 16-64 (thousands) | AK2: Student | AL2: Looking after family / home | AM2: Temp sick | AN2: Long-term sick | AO2: Retired | AP2: Other2 | AQ2: Total does not want a job aged 16-64 | AR2: Student | AS2: Looking after family / home | AT2: Temp sick | AU2: Long-term sick | AV2: Retired | AW2: Other2
A3: Current | B3: {=INDEX(B$18:B$1048576,COUNTA(B$18:B$1048576))} -> 9098658.3 | C3: {=INDEX(C$30:C$1048576,COUNTA(C$30:C$1048576))} -> 2349638 | D3: {=INDEX(D$30:D$1048576,COUNTA(D$30:D$1048576))} -> 1585084.5 | E3: {=INDEX(E$30:E$1048576,COUNTA(E$30:E$1048576))} -> 189524.3 | F3: {=INDEX(F$30:F$1048576,COUNTA(F$30:F$1048576))} -> 2810366.6 | G3: {=INDEX(G$30:G$1048576,COUNTA(G$30:G$1048576))} -> 40985.795 | H3: {=INDEX(H$30:H$1048576,COUNTA(H$30:H$1048576))} -> 1042702.3 | I3: {=INDEX(I$30:I$1048576,COUNTA(I$30:I$1048576))} -> 1080356.8 | J3: {=INDEX(J$30:J$1048576,COUNTA(J$30:J$1048576))} -> 6967924 | K3: {=INDEX(K$30:K$1048576,COUNTA(K$30:K$1048576))} -> 2130734.3 | L3: {=INDEX(L$18:L$1048576,COUNTA(L$18:L$1048576))} -> 100 | M3: {=INDEX(M$30:M$1048576,COUNTA(M$30:M$1048576))} -> 25.824005 | N3: {=INDEX(N$30:N$1048576,COUNTA(N$30:N$1048576))} -> 17.421079 | O3: {=INDEX(O$30:O$1048576,COUNTA(O$30:O$1048576))} -> 2.0829917 | P3: {=INDEX(P$30:P$1048576,COUNTA(P$30:P$1048576))} -> 30.887704 | Q3: {=INDEX(Q$30:Q$1048576,COUNTA(Q$30:Q$1048576))} -> 0.45045976 | R3: {=INDEX(R$30:R$1048576,COUNTA(R$30:R$1048576))} -> 11.459956 | S3: {=INDEX(S$30:S$1048576,COUNTA(S$30:S$1048576))} -> 11.873804 | T3: {=INDEX(T$30:T$1048576,COUNTA(T$30:T$1048576))} -> 76.581885 | U3: {=INDEX(U$30:U$1048576,COUNTA(U$30:U$1048576))} -> 23.418115 | V3: {=INDEX(V$18:V$1048576,COUNTA(V$18:V$1048576))} -> 2130734.3 | W3: {=INDEX(W$18:W$1048576,COUNTA(W$18:W$1048576))} -> 519773.77 | X3: {=INDEX(X$18:X$1048576,COUNTA(X$18:X$1048576))} -> 392475.66 | Y3: {=INDEX(Y$18:Y$1048576,COUNTA(Y$18:Y$1048576))} -> 93116.24 | Z3: {=INDEX(Z$18:Z$1048576,COUNTA(Z$18:Z$1048576))} -> 738422.59 | AA3: {=INDEX(AA$18:AA$1048576,COUNTA(AA$18:AA$1048576))} -> 27848.593 | AB3: {=INDEX(AB$18:AB$1048576,COUNTA(AB$18:AB$1048576))} -> 359183.3 | AC3: {=INDEX(AC$18:AC$1048576,COUNTA(AC$18:AC$1048576))} -> 100 | ... AW3: {=INDEX(AW$18:AW$1048576,COUNTA(AW$18:AW$1048576))} -> 10.430023
A4: Quarterly change | B4: {=INDEX(B$18:B$1048576,COUNTA(B$18:B$1048576))-INDEX(B$18:B$1048576,COUNTA(B$18:B$1048576)-3)} -> -25615.944 | C4: {=INDEX(C$18:C$1048576,COUNTA(C$18:C$1048576))-INDEX(C$18:C$1048576,COUNTA(C$18:C$1048576)-3)} -> -18212.587 | D4: {=INDEX(D$18:D$1048576,COUNTA(D$18:D$1048576))-INDEX(D$18:D$1048576,COUNTA(D$18:D$1048576)-3)} -> -29939.805 | E4: {=INDEX(E$18:E$1048576,COUNTA(E$18:E$1048576))-INDEX(E$18:E$1048576,COUNTA(E$18:E$1048576)-3)} -> -3000.4557 | F4: {=INDEX(F$18:F$1048576,COUNTA(F$18:F$1048576))-INDEX(F$18:F$1048576,COUNTA(F$18:F$1048576)-3)} -> 13296.123 | G4: {=INDEX(G$18:G$1048576,COUNTA(G$18:G$1048576))-INDEX(G$18:G$1048576,COUNTA(G$18:G$1048576)-3)} -> 13992.131 | H4: {=INDEX(H$18:H$1048576,COUNTA(H$18:H$1048576))-INDEX(H$18:H$1048576,COUNTA(H$18:H$1048576)-3)} -> 1653.9174 | I4: {=INDEX(I$18:I$1048576,COUNTA(I$18:I$1048576))-INDEX(I$18:I$1048576,COUNTA(I$18:I$1048576)-3)} -> -3405.2681 | ... AW4: {=INDEX(AW$18:AW$1048576,COUNTA(AW$18:AW$1048576))-INDEX(AW$18:AW$1048576,COUNTA(AW$18:AW$1048576)-3)} -> -0.1935363
A5: year on year change | B5: {=INDEX(B$18:B$1048576,COUNTA(B$18:B$1048576))-INDEX(B$18:B$1048576,COUNTA(B$18:B$1048576)-12)} -> -234336.28 | C5: {=INDEX(C$18:C$1048576,COUNTA(C$18:C$1048576))-INDEX(C$18:C$1048576,COUNTA(C$18:C$1048576)-12)} -> -116542.86 | D5: {=INDEX(D$18:D$1048576,COUNTA(D$18:D$1048576))-INDEX(D$18:D$1048576,COUNTA(D$18:D$1048576)-12)} -> -99983.743 | E5: {=INDEX(E$18:E$1048576,COUNTA(E$18:E$1048576))-INDEX(E$18:E$1048576,COUNTA(E$18:E$1048576)-12)} -> -8531.7342 | F5: {=INDEX(F$18:F$1048576,COUNTA(F$18:F$1048576))-INDEX(F$18:F$1048576,COUNTA(F$18:F$1048576)-12)} -> 15412.858 | G5: {=INDEX(G$18:G$1048576,COUNTA(G$18:G$1048576))-INDEX(G$18:G$1048576,COUNTA(G$18:G$1048576)-12)} -> 15502.771 | H5: {=INDEX(H$18:H$1048576,COUNTA(H$18:H$1048576))-INDEX(H$18:H$1048576,COUNTA(H$18:H$1048576)-12)} -> -52575.374 | I5: {=INDEX(I$18:I$1048576,COUNTA(I$18:I$1048576))-INDEX(I$18:I$1048576,COUNTA(I$18:I$1048576)-12)} -> 12381.803 | ... AW5: {=INDEX(AW$18:AW$1048576,COUNTA(AW$18:AW$1048576))-INDEX(AW$18:AW$1048576,COUNTA(AW$18:AW$1048576)-12)} -> 0.44781369
